<mujoco model="5_3D_model_w_N25_linear">
  <compiler inertiafromgeom="auto" angle="radian" />
   <option timestep="0.0001" iterations="50" solver="PGS" integrator="Euler" gravity="0 0 -9.81" collision="all">
     <flag energy="enable" />
   </option>
   <asset>
     <texture type="skybox" builtin="flat" rgb1="1 1 1" rgb2="1 1 1" width="100" height="100" />
      <material name="JointColor" rgba="1.0 1.0 0.0 1" />
      <material name="LimbColor" rgba="0.7 0.7 0.7 1" />
      <material name="pointMassColor" rgba="1.0 1.0 1.0 1.0" />
      <material name="RefMassColor" rgba="0.2 0.9 0.1 1.0" />
   </asset>
   <worldbody>
     <body name="cameramover" mocap="true" pos="0 0 0">
        <camera name="mycamera" pos="0.0 2.0 2.0" euler="1.5707 0 0" />
      </body>
      <body name="body_upper_arm" pos="0 0 0" euler="0 0 0">
        <inertial pos="0 0 -0.129" mass="1.595" diaginertia="0.011917 0.011937 0.001325" />
         <geom name="geom_shoulder" type="sphere" pos="0 0 0" material="JointColor" size="0.0294" mass="0" />
         <joint name="joint_shoulder_flex_ext" ref="0" type="hinge" stiffness="0" pos = "0 0 0" axis = "0 -1 0" />
         <joint name='joint_shoulder_add_abd' ref='0'  type='hinge' stiffness='0' pos='0 0 0' axis='-1 0 0' />
         <joint name='joint_shoulder_med_lat' ref='0'  type='hinge' stiffness='0' pos='0 0 0' axis=' 0 0 1' />
         <site name="site_upper_arm_COM" pos="0 0 -0.129" />
         <geom type="cylinder" fromto="0 0 0 0 0 -0.294" material="LimbColor" mass="0" size="0.0147" />
         <body name="body_fore_arm" pos="0 0 -0.294" euler="0 0 0">
           <inertial pos="0 0 -0.112" mass="0.869" diaginertia="0.004765 0.004855 0.000472" />
            <geom name="geom_elbow" type="sphere" pos="0 0 0" material="JointColor" size="0.0294" mass="0" />
            <joint name="joint_elbow" ref="0" type="hinge" stiffness="0" pos="0 0 0" axis="0 -1 0" />
            <geom type="cylinder" fromto="0 0 0 0 0 -0.291" material="LimbColor" mass="0" size="0.0147" />
            <site name="site_fore_arm_COM" pos="0 0 -0.112" />
            <geom name="geom_end_effector" type="sphere" pos="0 0 -0.291" material="JointColor" size="0.0294" mass="0" />
            <body name="body_node1" euler="0 0 0" pos="0 0 -0.291">
              <joint name="joint_node1_X" type="hinge" axis="1 0 0" pos="0 0 0" springref="0" stiffness="0" damping="0" />
               <joint name="joint_node1_Y" type="hinge" axis="0 -1 0" pos="0 0 0" springref="0" stiffness="0" damping="0" />
               <geom type="cylinder" fromto="0 0 0 0 0 -0.0720" size="0.0122176" mass="0" />
               <geom name="geom_1" type="sphere" material="pointMassColor" pos="0 0 -0.0720" size="0.0244352" mass="0.0345792" />
               <body name="body_node2" euler="0 0 0" pos="0 0 -0.0720">
                 <joint name="joint_node2_X" type="hinge" axis="1 0 0" pos="0 0 0" springref="0" stiffness="0.6415903999999999" damping="0.24391039999999997" />
                  <joint name="joint_node2_Y" type="hinge" axis="0 -1 0" pos="0 0 0" springref="0" stiffness="0.6415903999999999" damping="0.24391039999999997" />
                  <geom type="cylinder" fromto="0 0 0 0 0 -0.0720" size="0.0117189" mass="0" />
                  <geom name="geom_2" type="sphere" material="pointMassColor" pos="0 0 -0.0720" size="0.0234379" mass="0.0318144" />
                  <body name="body_node3" euler="0 0 0" pos="0 0 -0.0720">
                    <joint name="joint_node3_X" type="hinge" axis="1 0 0" pos="0 0 0" springref="0" stiffness="0.5881568" damping="0.2235968" />
                     <joint name="joint_node3_Y" type="hinge" axis="0 -1 0" pos="0 0 0" springref="0" stiffness="0.5881568" damping="0.2235968" />
                     <geom type="cylinder" fromto="0 0 0 0 0 -0.0720" size="0.0112203" mass="0" />
                     <geom name="geom_3" type="sphere" material="pointMassColor" pos="0 0 -0.0720" size="0.0224405" mass="0.0291648" />
                     <body name="body_node4" euler="0 0 0" pos="0 0 -0.0720">
                       <joint name="joint_node4_X" type="hinge" axis="1 0 0" pos="0 0 0" springref="0" stiffness="0.5370463999999999" damping="0.20416639999999997" />
                        <joint name="joint_node4_Y" type="hinge" axis="0 -1 0" pos="0 0 0" springref="0" stiffness="0.5370463999999999" damping="0.20416639999999997" />
                        <geom type="cylinder" fromto="0 0 0 0 0 -0.0720" size="0.0107216" mass="0" />
                        <geom name="geom_4" type="sphere" material="pointMassColor" pos="0 0 -0.0720" size="0.0214431" mass="0.0266304" />
                        <body name="body_node5" euler="0 0 0" pos="0 0 -0.0720">
                          <joint name="joint_node5_X" type="hinge" axis="1 0 0" pos="0 0 0" springref="0" stiffness="0.4882591999999999" damping="0.18561919999999998" />
                           <joint name="joint_node5_Y" type="hinge" axis="0 -1 0" pos="0 0 0" springref="0" stiffness="0.4882591999999999" damping="0.18561919999999998" />
                           <geom type="cylinder" fromto="0 0 0 0 0 -0.0720" size="0.0102229" mass="0" />
                           <geom name="geom_5" type="sphere" material="pointMassColor" pos="0 0 -0.0720" size="0.0204458" mass="0.0242112" />
                           <body name="body_node6" euler="0 0 0" pos="0 0 -0.0720">
                             <joint name="joint_node6_X" type="hinge" axis="1 0 0" pos="0 0 0" springref="0" stiffness="0.44179519999999994" damping="0.16795519999999997" />
                              <joint name="joint_node6_Y" type="hinge" axis="0 -1 0" pos="0 0 0" springref="0" stiffness="0.44179519999999994" damping="0.16795519999999997" />
                              <geom type="cylinder" fromto="0 0 0 0 0 -0.0720" size="0.0097242" mass="0" />
                              <geom name="geom_6" type="sphere" material="pointMassColor" pos="0 0 -0.0720" size="0.0194484" mass="0.0219072" />
                              <body name="body_node7" euler="0 0 0" pos="0 0 -0.0720">
                                <joint name="joint_node7_X" type="hinge" axis="1 0 0" pos="0 0 0" springref="0" stiffness="0.3976544" damping="0.15117440000000001" />
                                 <joint name="joint_node7_Y" type="hinge" axis="0 -1 0" pos="0 0 0" springref="0" stiffness="0.3976544" damping="0.15117440000000001" />
                                 <geom type="cylinder" fromto="0 0 0 0 0 -0.0720" size="0.0092255" mass="0" />
                                 <geom name="geom_7" type="sphere" material="pointMassColor" pos="0 0 -0.0720" size="0.0184511" mass="0.0197184" />
                                 <body name="body_node8" euler="0 0 0" pos="0 0 -0.0720">
                                   <joint name="joint_node8_X" type="hinge" axis="1 0 0" pos="0 0 0" springref="0" stiffness="0.3558368000000003" damping="0.13527680000000009" />
                                    <joint name="joint_node8_Y" type="hinge" axis="0 -1 0" pos="0 0 0" springref="0" stiffness="0.3558368000000003" damping="0.13527680000000009" />
                                    <geom type="cylinder" fromto="0 0 0 0 0 -0.0720" size="0.0087269" mass="0" />
                                    <geom name="geom_8" type="sphere" material="pointMassColor" pos="0 0 -0.0720" size="0.0174537" mass="0.0176448" />
                                    <body name="body_node9" euler="0 0 0" pos="0 0 -0.0720">
                                      <joint name="joint_node9_X" type="hinge" axis="1 0 0" pos="0 0 0" springref="0" stiffness="0.3163424000000002" damping="0.12026240000000007" />
                                       <joint name="joint_node9_Y" type="hinge" axis="0 -1 0" pos="0 0 0" springref="0" stiffness="0.3163424000000002" damping="0.12026240000000007" />
                                       <geom type="cylinder" fromto="0 0 0 0 0 -0.0720" size="0.0082282" mass="0" />
                                       <geom name="geom_9" type="sphere" material="pointMassColor" pos="0 0 -0.0720" size="0.0164564" mass="0.0156864" />
                                       <body name="body_node10" euler="0 0 0" pos="0 0 -0.0720">
                                         <joint name="joint_node10_X" type="hinge" axis="1 0 0" pos="0 0 0" springref="0" stiffness="0.2791711999999996" damping="0.10613119999999986" />
                                          <joint name="joint_node10_Y" type="hinge" axis="0 -1 0" pos="0 0 0" springref="0" stiffness="0.2791711999999996" damping="0.10613119999999986" />
                                          <geom type="cylinder" fromto="0 0 0 0 0 -0.0720" size="0.0077295" mass="0" />
                                          <geom name="geom_10" type="sphere" material="pointMassColor" pos="0 0 -0.0720" size="0.0154590" mass="0.0138432" />
                                          <body name="body_node11" euler="0 0 0" pos="0 0 -0.0720">
                                            <joint name="joint_node11_X" type="hinge" axis="1 0 0" pos="0 0 0" springref="0" stiffness="0.24432320000000013" damping="0.09288320000000005" />
                                             <joint name="joint_node11_Y" type="hinge" axis="0 -1 0" pos="0 0 0" springref="0" stiffness="0.24432320000000013" damping="0.09288320000000005" />
                                             <geom type="cylinder" fromto="0 0 0 0 0 -0.0720" size="0.0072308" mass="0" />
                                             <geom name="geom_11" type="sphere" material="pointMassColor" pos="0 0 -0.0720" size="0.0144617" mass="0.0121152" />
                                             <body name="body_node12" euler="0 0 0" pos="0 0 -0.0720">
                                               <joint name="joint_node12_X" type="hinge" axis="1 0 0" pos="0 0 0" springref="0" stiffness="0.21179840000000016" damping="0.08051840000000006" />
                                                <joint name="joint_node12_Y" type="hinge" axis="0 -1 0" pos="0 0 0" springref="0" stiffness="0.21179840000000016" damping="0.08051840000000006" />
                                                <geom type="cylinder" fromto="0 0 0 0 0 -0.0720" size="0.0067322" mass="0" />
                                                <geom name="geom_12" type="sphere" material="pointMassColor" pos="0 0 -0.0720" size="0.0134643" mass="0.0105024" />
                                                <body name="body_node13" euler="0 0 0" pos="0 0 -0.0720">
                                                  <joint name="joint_node13_X" type="hinge" axis="1 0 0" pos="0 0 0" springref="0" stiffness="0.1815968000000001" damping="0.06903680000000004" />
                                                   <joint name="joint_node13_Y" type="hinge" axis="0 -1 0" pos="0 0 0" springref="0" stiffness="0.1815968000000001" damping="0.06903680000000004" />
                                                   <geom type="cylinder" fromto="0 0 0 0 0 -0.0720" size="0.0062335" mass="0" />
                                                   <geom name="geom_13" type="sphere" material="pointMassColor" pos="0 0 -0.0720" size="0.0124669" mass="0.0090048" />
                                                   <body name="body_node14" euler="0 0 0" pos="0 0 -0.0720">
                                                     <joint name="joint_node14_X" type="hinge" axis="1 0 0" pos="0 0 0" springref="0" stiffness="0.15371840000000014" damping="0.05843840000000006" />
                                                      <joint name="joint_node14_Y" type="hinge" axis="0 -1 0" pos="0 0 0" springref="0" stiffness="0.15371840000000014" damping="0.05843840000000006" />
                                                      <geom type="cylinder" fromto="0 0 0 0 0 -0.0720" size="0.0057348" mass="0" />
                                                      <geom name="geom_14" type="sphere" material="pointMassColor" pos="0 0 -0.0720" size="0.0114696" mass="0.0076224" />
                                                      <body name="body_node15" euler="0 0 0" pos="0 0 -0.0720">
                                                        <joint name="joint_node15_X" type="hinge" axis="1 0 0" pos="0 0 0" springref="0" stiffness="0.12816320000000012" damping="0.04872320000000004" />
                                                         <joint name="joint_node15_Y" type="hinge" axis="0 -1 0" pos="0 0 0" springref="0" stiffness="0.12816320000000012" damping="0.04872320000000004" />
                                                         <geom type="cylinder" fromto="0 0 0 0 0 -0.0720" size="0.0052361" mass="0" />
                                                         <geom name="geom_15" type="sphere" material="pointMassColor" pos="0 0 -0.0720" size="0.0104722" mass="0.0063552" />
                                                         <body name="body_node16" euler="0 0 0" pos="0 0 -0.0720">
                                                           <joint name="joint_node16_X" type="hinge" axis="1 0 0" pos="0 0 0" springref="0" stiffness="0.10493120000000007" damping="0.03989120000000002" />
                                                            <joint name="joint_node16_Y" type="hinge" axis="0 -1 0" pos="0 0 0" springref="0" stiffness="0.10493120000000007" damping="0.03989120000000002" />
                                                            <geom type="cylinder" fromto="0 0 0 0 0 -0.0720" size="0.0047374" mass="0" />
                                                            <geom name="geom_16" type="sphere" material="pointMassColor" pos="0 0 -0.0720" size="0.0094749" mass="0.0052032" />
                                                            <body name="body_node17" euler="0 0 0" pos="0 0 -0.0720">
                                                              <joint name="joint_node17_X" type="hinge" axis="1 0 0" pos="0 0 0" springref="0" stiffness="0.08402240000000002" damping="0.03194240000000001" />
                                                               <joint name="joint_node17_Y" type="hinge" axis="0 -1 0" pos="0 0 0" springref="0" stiffness="0.08402240000000002" damping="0.03194240000000001" />
                                                               <geom type="cylinder" fromto="0 0 0 0 0 -0.0720" size="0.0042388" mass="0" />
                                                               <geom name="geom_17" type="sphere" material="pointMassColor" pos="0 0 -0.0720" size="0.0084775" mass="0.0041664" />
                                                               <body name="body_node18" euler="0 0 0" pos="0 0 -0.0720">
                                                                 <joint name="joint_node18_X" type="hinge" axis="1 0 0" pos="0 0 0" springref="0" stiffness="0.06543680000000003" damping="0.024876800000000008" />
                                                                  <joint name="joint_node18_Y" type="hinge" axis="0 -1 0" pos="0 0 0" springref="0" stiffness="0.06543680000000003" damping="0.024876800000000008" />
                                                                  <geom type="cylinder" fromto="0 0 0 0 0 -0.0720" size="0.0037401" mass="0" />
                                                                  <geom name="geom_18" type="sphere" material="pointMassColor" pos="0 0 -0.0720" size="0.0074802" mass="0.0032448" />
                                                                  <body name="body_node19" euler="0 0 0" pos="0 0 -0.0720">
                                                                    <joint name="joint_node19_X" type="hinge" axis="1 0 0" pos="0 0 0" springref="0" stiffness="0.049174400000000035" damping="0.018694400000000014" />
                                                                     <joint name="joint_node19_Y" type="hinge" axis="0 -1 0" pos="0 0 0" springref="0" stiffness="0.049174400000000035" damping="0.018694400000000014" />
                                                                     <geom type="cylinder" fromto="0 0 0 0 0 -0.0720" size="0.0032414" mass="0" />
                                                                     <geom name="geom_19" type="sphere" material="pointMassColor" pos="0 0 -0.0720" size="0.0064828" mass="0.0024384" />
                                                                     <body name="body_node20" euler="0 0 0" pos="0 0 -0.0720">
                                                                       <joint name="joint_node20_X" type="hinge" axis="1 0 0" pos="0 0 0" springref="0" stiffness="0.03523520000000002" damping="0.013395200000000008" />
                                                                        <joint name="joint_node20_Y" type="hinge" axis="0 -1 0" pos="0 0 0" springref="0" stiffness="0.03523520000000002" damping="0.013395200000000008" />
                                                                        <geom type="cylinder" fromto="0 0 0 0 0 -0.0720" size="0.0027427" mass="0" />
                                                                        <geom name="geom_20" type="sphere" material="pointMassColor" pos="0 0 -0.0720" size="0.0054855" mass="0.0017472" />
                                                                        <body name="body_node21" euler="0 0 0" pos="0 0 -0.0720">
                                                                          <joint name="joint_node21_X" type="hinge" axis="1 0 0" pos="0 0 0" springref="0" stiffness="0.0236192" damping="0.0089792" />
                                                                           <joint name="joint_node21_Y" type="hinge" axis="0 -1 0" pos="0 0 0" springref="0" stiffness="0.0236192" damping="0.0089792" />
                                                                           <geom type="cylinder" fromto="0 0 0 0 0 -0.0720" size="0.0022441" mass="0" />
                                                                           <geom name="geom_21" type="sphere" material="pointMassColor" pos="0 0 -0.0720" size="0.0044881" mass="0.0011712" />
                                                                           <body name="body_node22" euler="0 0 0" pos="0 0 -0.0720">
                                                                             <joint name="joint_node22_X" type="hinge" axis="1 0 0" pos="0 0 0" springref="0" stiffness="0.014326400000000017" damping="0.005446400000000007" />
                                                                              <joint name="joint_node22_Y" type="hinge" axis="0 -1 0" pos="0 0 0" springref="0" stiffness="0.014326400000000017" damping="0.005446400000000007" />
                                                                              <geom type="cylinder" fromto="0 0 0 0 0 -0.0720" size="0.0017454" mass="0" />
                                                                              <geom name="geom_22" type="sphere" material="pointMassColor" pos="0 0 -0.0720" size="0.0034907" mass="0.0007104" />
                                                                              <body name="body_node23" euler="0 0 0" pos="0 0 -0.0720">
                                                                                <joint name="joint_node23_X" type="hinge" axis="1 0 0" pos="0 0 0" springref="0" stiffness="0.007356800000000006" damping="0.002796800000000002" />
                                                                                 <joint name="joint_node23_Y" type="hinge" axis="0 -1 0" pos="0 0 0" springref="0" stiffness="0.007356800000000006" damping="0.002796800000000002" />
                                                                                 <geom type="cylinder" fromto="0 0 0 0 0 -0.0720" size="0.0012467" mass="0" />
                                                                                 <geom name="geom_23" type="sphere" material="pointMassColor" pos="0 0 -0.0720" size="0.0024934" mass="0.0003648" />
                                                                                 <body name="body_node24" euler="0 0 0" pos="0 0 -0.0720">
                                                                                   <joint name="joint_node24_X" type="hinge" axis="1 0 0" pos="0 0 0" springref="0" stiffness="0.002710400000000001" damping="0.0010304000000000003" />
                                                                                    <joint name="joint_node24_Y" type="hinge" axis="0 -1 0" pos="0 0 0" springref="0" stiffness="0.002710400000000001" damping="0.0010304000000000003" />
                                                                                    <geom type="cylinder" fromto="0 0 0 0 0 -0.0720" size="0.0007480" mass="0" />
                                                                                    <geom name="geom_24" type="sphere" material="pointMassColor" pos="0 0 -0.0720" size="0.0014960" mass="0.0001344" />
                                                                                    <body name="body_node25" euler="0 0 0" pos="0 0 -0.0720">
                                                                                      <joint name="joint_node25_X" type="hinge" axis="1 0 0" pos="0 0 0" springref="0" stiffness="0.0003871999999999983" damping="0.00014719999999999935" />
                                                                                       <joint name="joint_node25_Y" type="hinge" axis="0 -1 0" pos="0 0 0" springref="0" stiffness="0.0003871999999999983" damping="0.00014719999999999935" />
                                                                                       <geom type="cylinder" fromto="0 0 0 0 0 -0.0720" size="0.0002493" mass="0" />
                                                                                       <geom name="geom_25_tip" type="sphere" material="pointMassColor" pos="0 0 -0.0720" size="0.0004987" mass="0.0000192" />
                                                                                    </body>
                                                                                 </body>
                                                                              </body>
                                                                           </body>
                                                                        </body>
                                                                     </body>
                                                                  </body>
                                                               </body>
                                                            </body>
                                                         </body>
                                                      </body>
                                                   </body>
                                                </body>
                                             </body>
                                          </body>
                                       </body>
                                    </body>
                                 </body>
                              </body>
                           </body>
                        </body>
                     </body>
                  </body>
               </body>
            </body>
            <!-- === [ N, L, M, k, b, rho ] = [25,1.800000,0.300000,0.242000,0.092000,1.000000] -->
         </body>
      </body>
      <geom name="geom_target" type="sphere" pos="2.395 0 0" rgba="1 0 0 1" mass="0" size="0.03"  />

     </worldbody>


     <actuator>
        <motor joint="joint_shoulder_flex_ext" name="motor_shoulder_flex_ext" forcelimited="false" />
        <motor joint="joint_shoulder_add_abd"  name="motor_shoulder_add_abd"  forcelimited="false" />
        <motor joint="joint_shoulder_med_lat"  name="motor_shoulder_med_lat"  forcelimited="false" />
        <motor joint="joint_elbow" 						 name="motor_elbow" 						forcelimited="false" />
     </actuator>
</mujoco>
