<mujoco model="5_3D_model_w_N25_linear">
  <compiler inertiafromgeom="auto" angle="radian" />
   <option timestep="0.0001" iterations="50" solver="PGS" integrator="Euler" gravity="0 0 -9.81" collision="all">
     <flag energy="enable" />
   </option>
   <asset>
     <texture type="skybox" builtin="flat" rgb1="1 1 1" rgb2="1 1 1" width="100" height="100" />
      <material name="JointColor" rgba="1.0 1.0 0.0 1" />
      <material name="LimbColor" rgba="0.7 0.7 0.7 1" />
      <material name="pointMassColor" rgba="1.0 1.0 1.0 1.0" />
      <material name="RefMassColor" rgba="0.2 0.9 0.1 1.0" />
   </asset>
   <worldbody>
     <body name="cameramover" mocap="true" pos="0 0 0">
        <camera name="mycamera" pos="0.0 2.0 2.0" euler="1.5707 0 0" />
      </body>
      <body name="upperArm" pos="0 0 0" euler="0 0 0">
        <inertial pos="0 0 -0.129" mass="1.595" diaginertia="0.011917 0.011937 0.001325" />
         <geom name="shoulderGEOM" type="sphere" pos="0 0 0" material="JointColor" size="0.0294" mass="0" />
         <joint name="shoulderFlexExt" ref="0" type="hinge" stiffness="0" pos="0 0 0" axis="0 -1 0" />
         <joint name="shoulderAddAbd" ref="0" type="hinge" stiffness="0" pos="0 0 0" axis="-1 0 0" />
         <joint name="shoulderMedLat" ref="0" type="hinge" stiffness="0" pos="0 0 0" axis=" 0 0 1" />
         <site name="upperArmCOM" pos="0 0 -0.129" />
         <geom type="cylinder" fromto="0 0 0 0 0 -0.294" material="LimbColor" mass="0" size="0.0147" />
         <body name="foreArm" pos="0 0 -0.294" euler="0 0 0">
           <inertial pos="0 0 -0.112" mass="0.869" diaginertia="0.004765 0.004855 0.000472" />
            <geom name="elbowGEOM" type="sphere" pos="0 0 0" material="JointColor" size="0.0294" mass="0" />
            <joint name="elbow" ref="0" type="hinge" stiffness="0" pos="0 0 0" axis="0 -1 0" />
            <geom type="cylinder" fromto="0 0 0 0 0 -0.291" material="LimbColor" mass="0" size="0.0147" />
            <site name="foreArmCOM" pos="0 0 -0.112" />
            <geom name="geom_EE" type="sphere" pos="0 0 -0.291" material="JointColor" size="0.0294" mass="0" />
            <body name="node1" euler="0 0 0" pos="0 0 -0.291">
              <joint name="node1JointX" type="hinge" axis="1 0 0" pos="0 0 0" springref="0" stiffness="0" damping="0" />
               <joint name="node1JointY" type="hinge" axis="0 -1 0" pos="0 0 0" springref="0" stiffness="0" damping="0" />
               <geom type="cylinder" fromto="0 0 0 0 0 -0.0720" size="0.0122176" mass="0" />
               <geom name="geom1" type="sphere" material="pointMassColor" pos="0 0 -0.0720" size="0.0244352" mass="0.0345792" />
               <body name="node2" euler="0 0 0" pos="0 0 -0.0720">
                 <joint name="node2JointX" type="hinge" axis="1 0 0" pos="0 0 0" springref="0" stiffness="0.6415903999999999" damping="0.24391039999999997" />
                  <joint name="node2JointY" type="hinge" axis="0 -1 0" pos="0 0 0" springref="0" stiffness="0.6415903999999999" damping="0.24391039999999997" />
                  <geom type="cylinder" fromto="0 0 0 0 0 -0.0720" size="0.0117189" mass="0" />
                  <geom name="geom2" type="sphere" material="pointMassColor" pos="0 0 -0.0720" size="0.0234379" mass="0.0318144" />
                  <body name="node3" euler="0 0 0" pos="0 0 -0.0720">
                    <joint name="node3JointX" type="hinge" axis="1 0 0" pos="0 0 0" springref="0" stiffness="0.5881568" damping="0.2235968" />
                     <joint name="node3JointY" type="hinge" axis="0 -1 0" pos="0 0 0" springref="0" stiffness="0.5881568" damping="0.2235968" />
                     <geom type="cylinder" fromto="0 0 0 0 0 -0.0720" size="0.0112203" mass="0" />
                     <geom name="geom3" type="sphere" material="pointMassColor" pos="0 0 -0.0720" size="0.0224405" mass="0.0291648" />
                     <body name="node4" euler="0 0 0" pos="0 0 -0.0720">
                       <joint name="node4JointX" type="hinge" axis="1 0 0" pos="0 0 0" springref="0" stiffness="0.5370463999999999" damping="0.20416639999999997" />
                        <joint name="node4JointY" type="hinge" axis="0 -1 0" pos="0 0 0" springref="0" stiffness="0.5370463999999999" damping="0.20416639999999997" />
                        <geom type="cylinder" fromto="0 0 0 0 0 -0.0720" size="0.0107216" mass="0" />
                        <geom name="geom4" type="sphere" material="pointMassColor" pos="0 0 -0.0720" size="0.0214431" mass="0.0266304" />
                        <body name="node5" euler="0 0 0" pos="0 0 -0.0720">
                          <joint name="node5JointX" type="hinge" axis="1 0 0" pos="0 0 0" springref="0" stiffness="0.4882591999999999" damping="0.18561919999999998" />
                           <joint name="node5JointY" type="hinge" axis="0 -1 0" pos="0 0 0" springref="0" stiffness="0.4882591999999999" damping="0.18561919999999998" />
                           <geom type="cylinder" fromto="0 0 0 0 0 -0.0720" size="0.0102229" mass="0" />
                           <geom name="geom5" type="sphere" material="pointMassColor" pos="0 0 -0.0720" size="0.0204458" mass="0.0242112" />
                           <body name="node6" euler="0 0 0" pos="0 0 -0.0720">
                             <joint name="node6JointX" type="hinge" axis="1 0 0" pos="0 0 0" springref="0" stiffness="0.44179519999999994" damping="0.16795519999999997" />
                              <joint name="node6JointY" type="hinge" axis="0 -1 0" pos="0 0 0" springref="0" stiffness="0.44179519999999994" damping="0.16795519999999997" />
                              <geom type="cylinder" fromto="0 0 0 0 0 -0.0720" size="0.0097242" mass="0" />
                              <geom name="geom6" type="sphere" material="pointMassColor" pos="0 0 -0.0720" size="0.0194484" mass="0.0219072" />
                              <body name="node7" euler="0 0 0" pos="0 0 -0.0720">
                                <joint name="node7JointX" type="hinge" axis="1 0 0" pos="0 0 0" springref="0" stiffness="0.3976544" damping="0.15117440000000001" />
                                 <joint name="node7JointY" type="hinge" axis="0 -1 0" pos="0 0 0" springref="0" stiffness="0.3976544" damping="0.15117440000000001" />
                                 <geom type="cylinder" fromto="0 0 0 0 0 -0.0720" size="0.0092255" mass="0" />
                                 <geom name="geom7" type="sphere" material="pointMassColor" pos="0 0 -0.0720" size="0.0184511" mass="0.0197184" />
                                 <body name="node8" euler="0 0 0" pos="0 0 -0.0720">
                                   <joint name="node8JointX" type="hinge" axis="1 0 0" pos="0 0 0" springref="0" stiffness="0.3558368000000003" damping="0.13527680000000009" />
                                    <joint name="node8JointY" type="hinge" axis="0 -1 0" pos="0 0 0" springref="0" stiffness="0.3558368000000003" damping="0.13527680000000009" />
                                    <geom type="cylinder" fromto="0 0 0 0 0 -0.0720" size="0.0087269" mass="0" />
                                    <geom name="geom8" type="sphere" material="pointMassColor" pos="0 0 -0.0720" size="0.0174537" mass="0.0176448" />
                                    <body name="node9" euler="0 0 0" pos="0 0 -0.0720">
                                      <joint name="node9JointX" type="hinge" axis="1 0 0" pos="0 0 0" springref="0" stiffness="0.3163424000000002" damping="0.12026240000000007" />
                                       <joint name="node9JointY" type="hinge" axis="0 -1 0" pos="0 0 0" springref="0" stiffness="0.3163424000000002" damping="0.12026240000000007" />
                                       <geom type="cylinder" fromto="0 0 0 0 0 -0.0720" size="0.0082282" mass="0" />
                                       <geom name="geom9" type="sphere" material="pointMassColor" pos="0 0 -0.0720" size="0.0164564" mass="0.0156864" />
                                       <body name="node10" euler="0 0 0" pos="0 0 -0.0720">
                                         <joint name="node10JointX" type="hinge" axis="1 0 0" pos="0 0 0" springref="0" stiffness="0.2791711999999996" damping="0.10613119999999986" />
                                          <joint name="node10JointY" type="hinge" axis="0 -1 0" pos="0 0 0" springref="0" stiffness="0.2791711999999996" damping="0.10613119999999986" />
                                          <geom type="cylinder" fromto="0 0 0 0 0 -0.0720" size="0.0077295" mass="0" />
                                          <geom name="geom10" type="sphere" material="pointMassColor" pos="0 0 -0.0720" size="0.0154590" mass="0.0138432" />
                                          <body name="node11" euler="0 0 0" pos="0 0 -0.0720">
                                            <joint name="node11JointX" type="hinge" axis="1 0 0" pos="0 0 0" springref="0" stiffness="0.24432320000000013" damping="0.09288320000000005" />
                                             <joint name="node11JointY" type="hinge" axis="0 -1 0" pos="0 0 0" springref="0" stiffness="0.24432320000000013" damping="0.09288320000000005" />
                                             <geom type="cylinder" fromto="0 0 0 0 0 -0.0720" size="0.0072308" mass="0" />
                                             <geom name="geom11" type="sphere" material="pointMassColor" pos="0 0 -0.0720" size="0.0144617" mass="0.0121152" />
                                             <body name="node12" euler="0 0 0" pos="0 0 -0.0720">
                                               <joint name="node12JointX" type="hinge" axis="1 0 0" pos="0 0 0" springref="0" stiffness="0.21179840000000016" damping="0.08051840000000006" />
                                                <joint name="node12JointY" type="hinge" axis="0 -1 0" pos="0 0 0" springref="0" stiffness="0.21179840000000016" damping="0.08051840000000006" />
                                                <geom type="cylinder" fromto="0 0 0 0 0 -0.0720" size="0.0067322" mass="0" />
                                                <geom name="geom12" type="sphere" material="pointMassColor" pos="0 0 -0.0720" size="0.0134643" mass="0.0105024" />
                                                <body name="node13" euler="0 0 0" pos="0 0 -0.0720">
                                                  <joint name="node13JointX" type="hinge" axis="1 0 0" pos="0 0 0" springref="0" stiffness="0.1815968000000001" damping="0.06903680000000004" />
                                                   <joint name="node13JointY" type="hinge" axis="0 -1 0" pos="0 0 0" springref="0" stiffness="0.1815968000000001" damping="0.06903680000000004" />
                                                   <geom type="cylinder" fromto="0 0 0 0 0 -0.0720" size="0.0062335" mass="0" />
                                                   <geom name="geom13" type="sphere" material="pointMassColor" pos="0 0 -0.0720" size="0.0124669" mass="0.0090048" />
                                                   <body name="node14" euler="0 0 0" pos="0 0 -0.0720">
                                                     <joint name="node14JointX" type="hinge" axis="1 0 0" pos="0 0 0" springref="0" stiffness="0.15371840000000014" damping="0.05843840000000006" />
                                                      <joint name="node14JointY" type="hinge" axis="0 -1 0" pos="0 0 0" springref="0" stiffness="0.15371840000000014" damping="0.05843840000000006" />
                                                      <geom type="cylinder" fromto="0 0 0 0 0 -0.0720" size="0.0057348" mass="0" />
                                                      <geom name="geom14" type="sphere" material="pointMassColor" pos="0 0 -0.0720" size="0.0114696" mass="0.0076224" />
                                                      <body name="node15" euler="0 0 0" pos="0 0 -0.0720">
                                                        <joint name="node15JointX" type="hinge" axis="1 0 0" pos="0 0 0" springref="0" stiffness="0.12816320000000012" damping="0.04872320000000004" />
                                                         <joint name="node15JointY" type="hinge" axis="0 -1 0" pos="0 0 0" springref="0" stiffness="0.12816320000000012" damping="0.04872320000000004" />
                                                         <geom type="cylinder" fromto="0 0 0 0 0 -0.0720" size="0.0052361" mass="0" />
                                                         <geom name="geom15" type="sphere" material="pointMassColor" pos="0 0 -0.0720" size="0.0104722" mass="0.0063552" />
                                                         <body name="node16" euler="0 0 0" pos="0 0 -0.0720">
                                                           <joint name="node16JointX" type="hinge" axis="1 0 0" pos="0 0 0" springref="0" stiffness="0.10493120000000007" damping="0.03989120000000002" />
                                                            <joint name="node16JointY" type="hinge" axis="0 -1 0" pos="0 0 0" springref="0" stiffness="0.10493120000000007" damping="0.03989120000000002" />
                                                            <geom type="cylinder" fromto="0 0 0 0 0 -0.0720" size="0.0047374" mass="0" />
                                                            <geom name="geom16" type="sphere" material="pointMassColor" pos="0 0 -0.0720" size="0.0094749" mass="0.0052032" />
                                                            <body name="node17" euler="0 0 0" pos="0 0 -0.0720">
                                                              <joint name="node17JointX" type="hinge" axis="1 0 0" pos="0 0 0" springref="0" stiffness="0.08402240000000002" damping="0.03194240000000001" />
                                                               <joint name="node17JointY" type="hinge" axis="0 -1 0" pos="0 0 0" springref="0" stiffness="0.08402240000000002" damping="0.03194240000000001" />
                                                               <geom type="cylinder" fromto="0 0 0 0 0 -0.0720" size="0.0042388" mass="0" />
                                                               <geom name="geom17" type="sphere" material="pointMassColor" pos="0 0 -0.0720" size="0.0084775" mass="0.0041664" />
                                                               <body name="node18" euler="0 0 0" pos="0 0 -0.0720">
                                                                 <joint name="node18JointX" type="hinge" axis="1 0 0" pos="0 0 0" springref="0" stiffness="0.06543680000000003" damping="0.024876800000000008" />
                                                                  <joint name="node18JointY" type="hinge" axis="0 -1 0" pos="0 0 0" springref="0" stiffness="0.06543680000000003" damping="0.024876800000000008" />
                                                                  <geom type="cylinder" fromto="0 0 0 0 0 -0.0720" size="0.0037401" mass="0" />
                                                                  <geom name="geom18" type="sphere" material="pointMassColor" pos="0 0 -0.0720" size="0.0074802" mass="0.0032448" />
                                                                  <body name="node19" euler="0 0 0" pos="0 0 -0.0720">
                                                                    <joint name="node19JointX" type="hinge" axis="1 0 0" pos="0 0 0" springref="0" stiffness="0.049174400000000035" damping="0.018694400000000014" />
                                                                     <joint name="node19JointY" type="hinge" axis="0 -1 0" pos="0 0 0" springref="0" stiffness="0.049174400000000035" damping="0.018694400000000014" />
                                                                     <geom type="cylinder" fromto="0 0 0 0 0 -0.0720" size="0.0032414" mass="0" />
                                                                     <geom name="geom19" type="sphere" material="pointMassColor" pos="0 0 -0.0720" size="0.0064828" mass="0.0024384" />
                                                                     <body name="node20" euler="0 0 0" pos="0 0 -0.0720">
                                                                       <joint name="node20JointX" type="hinge" axis="1 0 0" pos="0 0 0" springref="0" stiffness="0.03523520000000002" damping="0.013395200000000008" />
                                                                        <joint name="node20JointY" type="hinge" axis="0 -1 0" pos="0 0 0" springref="0" stiffness="0.03523520000000002" damping="0.013395200000000008" />
                                                                        <geom type="cylinder" fromto="0 0 0 0 0 -0.0720" size="0.0027427" mass="0" />
                                                                        <geom name="geom20" type="sphere" material="pointMassColor" pos="0 0 -0.0720" size="0.0054855" mass="0.0017472" />
                                                                        <body name="node21" euler="0 0 0" pos="0 0 -0.0720">
                                                                          <joint name="node21JointX" type="hinge" axis="1 0 0" pos="0 0 0" springref="0" stiffness="0.0236192" damping="0.0089792" />
                                                                           <joint name="node21JointY" type="hinge" axis="0 -1 0" pos="0 0 0" springref="0" stiffness="0.0236192" damping="0.0089792" />
                                                                           <geom type="cylinder" fromto="0 0 0 0 0 -0.0720" size="0.0022441" mass="0" />
                                                                           <geom name="geom21" type="sphere" material="pointMassColor" pos="0 0 -0.0720" size="0.0044881" mass="0.0011712" />
                                                                           <body name="node22" euler="0 0 0" pos="0 0 -0.0720">
                                                                             <joint name="node22JointX" type="hinge" axis="1 0 0" pos="0 0 0" springref="0" stiffness="0.014326400000000017" damping="0.005446400000000007" />
                                                                              <joint name="node22JointY" type="hinge" axis="0 -1 0" pos="0 0 0" springref="0" stiffness="0.014326400000000017" damping="0.005446400000000007" />
                                                                              <geom type="cylinder" fromto="0 0 0 0 0 -0.0720" size="0.0017454" mass="0" />
                                                                              <geom name="geom22" type="sphere" material="pointMassColor" pos="0 0 -0.0720" size="0.0034907" mass="0.0007104" />
                                                                              <body name="node23" euler="0 0 0" pos="0 0 -0.0720">
                                                                                <joint name="node23JointX" type="hinge" axis="1 0 0" pos="0 0 0" springref="0" stiffness="0.007356800000000006" damping="0.002796800000000002" />
                                                                                 <joint name="node23JointY" type="hinge" axis="0 -1 0" pos="0 0 0" springref="0" stiffness="0.007356800000000006" damping="0.002796800000000002" />
                                                                                 <geom type="cylinder" fromto="0 0 0 0 0 -0.0720" size="0.0012467" mass="0" />
                                                                                 <geom name="geom23" type="sphere" material="pointMassColor" pos="0 0 -0.0720" size="0.0024934" mass="0.0003648" />
                                                                                 <body name="node24" euler="0 0 0" pos="0 0 -0.0720">
                                                                                   <joint name="node24JointX" type="hinge" axis="1 0 0" pos="0 0 0" springref="0" stiffness="0.002710400000000001" damping="0.0010304000000000003" />
                                                                                    <joint name="node24JointY" type="hinge" axis="0 -1 0" pos="0 0 0" springref="0" stiffness="0.002710400000000001" damping="0.0010304000000000003" />
                                                                                    <geom type="cylinder" fromto="0 0 0 0 0 -0.0720" size="0.0007480" mass="0" />
                                                                                    <geom name="geom24" type="sphere" material="pointMassColor" pos="0 0 -0.0720" size="0.0014960" mass="0.0001344" />
                                                                                    <body name="node25" euler="0 0 0" pos="0 0 -0.0720">
                                                                                      <joint name="node25JointX" type="hinge" axis="1 0 0" pos="0 0 0" springref="0" stiffness="0.0003871999999999983" damping="0.00014719999999999935" />
                                                                                       <joint name="node25JointY" type="hinge" axis="0 -1 0" pos="0 0 0" springref="0" stiffness="0.0003871999999999983" damping="0.00014719999999999935" />
                                                                                       <geom type="cylinder" fromto="0 0 0 0 0 -0.0720" size="0.0002493" mass="0" />
                                                                                       <geom name="geom25Tip" type="sphere" material="pointMassColor" pos="0 0 -0.0720" size="0.0004987" mass="0.0000192" />
                                                                                    </body>
                                                                                 </body>
                                                                              </body>
                                                                           </body>
                                                                        </body>
                                                                     </body>
                                                                  </body>
                                                               </body>
                                                            </body>
                                                         </body>
                                                      </body>
                                                   </body>
                                                </body>
                                             </body>
                                          </body>
                                       </body>
                                    </body>
                                 </body>
                              </body>
                           </body>
                        </body>
                     </body>
                  </body>
               </body>
            </body>
            <!-- === [ N, L, M, k, b, rho ] = [25,1.800000,0.300000,0.242000,0.092000,1.000000] -->
         </body>
      </body>
   </worldbody>
   <actuator>
     <motor joint="shoulderFlexExt" name="shoulderFlexExtTorqueMotor" forcelimited="false" />
      <motor joint="shoulderAddAbd" name="shoulderAddAbdTorqueMotor" forcelimited="false" />
      <motor joint="shoulderMedLat" name="shoulderMedLatTorqueMotor" forcelimited="false" />
      <motor joint="elbow" name="elbowTorqueMotor" forcelimited="false" />
   </actuator>
</mujoco>
