<mujoco model="1_3D_model_w_N25">
  <compiler inertiafromgeom="auto" angle="radian" />
   <!-- <option timestep="0.0001" iterations="50" solver="PGS" integrator="Euler" gravity="0 0 -9.81" collision="predefined"> -->
   <option timestep="0.0001" iterations="50" solver="PGS" integrator="Euler" gravity="0 0 0" collision="predefined">
     <flag energy="enable" />
   </option>
   <asset>
		 <texture type="skybox" builtin="checker" rgb1="1 1 1" rgb2="1 1 1" width="200" height="200"  />

     
		 <material name="JointColor" 		 rgba="0.1 0.1 0.1 1" />
		 <material name="LimbColor" 		 rgba="0.1 0.1 0.1 1" />
		 <material name="pointMassColor" rgba="0.75 0.0 0.75 1" />

		 
		 <material name="RefMassColor" 	 rgba="0.2 0.9 0.1 1.0" />

  </asset>

	<!-- Excluding the 5 bodies from the tip of the whip for target contact -->
	<!-- <contact>
		<exclude body1="body_node21" body2="body_target"/>
		<exclude body1="body_node22" body2="body_target"/>
		<exclude body1="body_node23" body2="body_target"/>
		<exclude body1="body_node24" body2="body_target"/>
		<exclude body1="body_node25" body2="body_target"/>
	</contact> -->

	<visual>
		<global glow="1.0" fovy="45" ipd="0.0"/>
		<headlight specular="0.0 0.0 0.0" diffuse="1.0 1.0 1.0"/>
	</visual>

   <worldbody>
     <body name="cameramover" mocap="true" pos="0 0 0">
        <camera name="mycamera" pos="0.0 2.0 2.0" euler="1.5707 0 0" />
      </body>

      <body name="body_excitator" euler="0 0 0" pos="0 0 0">
        <joint name="joint_excitator" type="slide" axis="1 0 0" pos="0 0 0" />
         <geom name="geom_excitator" type="sphere" material="pointMassColor" pos="0 0 0" size="0.01" mass="6" />
          <body name="body_whip_node1" euler="0 0 0" pos="0 0 0">
              <!-- <joint name="joint_whip_node1_X" type="hinge" axis="1  0 0" pos="0 0 0" springref="0" stiffness="0" damping="0" /> -->
              <joint name="joint_whip_node1_Y" type="hinge" axis="0 -1 0" pos="0 0 0" springref="0" stiffness="0.242" damping="0.092" />
               <geom type="cylinder" fromto="0 0 0 0 0 -0.0720" size="0.0100000" mass="0" />
               <geom name="geom_whip_node1" type="sphere" material="pointMassColor" pos="0 0 -0.0720" size="0.0200000" mass="0.0120000" />
               <body name="body_whip_node2" euler="0 0 0" pos="0 0 -0.0720">
                 <!-- <joint name="joint_whip_node2_X" type="hinge" axis="1  0 0" pos="0 0 0" springref="0" stiffness="0.242" damping="0.092" /> -->
                 <joint name="joint_whip_node2_Y" type="hinge" axis="0 -1 0" pos="0 0 0" springref="0" stiffness="0.242" damping="0.092" />
                  <geom type="cylinder" fromto="0 0 0 0 0 -0.0720" size="0.0100000" mass="0" />
                  <geom name="geom_whip_node2" type="sphere" material="pointMassColor" pos="0 0 -0.0720" size="0.0200000" mass="0.0120000" />
                  <body name="body_whip_node3" euler="0 0 0" pos="0 0 -0.0720">
                    <!-- <joint name="joint_whip_node3_X" type="hinge" axis="1  0 0" pos="0 0 0" springref="0" stiffness="0.242" damping="0.092" /> -->
                    <joint name="joint_whip_node3_Y" type="hinge" axis="0 -1 0" pos="0 0 0" springref="0" stiffness="0.242" damping="0.092" />
                     <geom type="cylinder" fromto="0 0 0 0 0 -0.0720" size="0.0100000" mass="0" />
                     <geom name="geom_whip_node3" type="sphere" material="pointMassColor" pos="0 0 -0.0720" size="0.0200000" mass="0.0120000" />
                     <body name="body_whip_node4" euler="0 0 0" pos="0 0 -0.0720">
                       <!-- <joint name="joint_whip_node4_X" type="hinge" axis="1  0 0" pos="0 0 0" springref="0" stiffness="0.242" damping="0.092" /> -->
                       <joint name="joint_whip_node4_Y" type="hinge" axis="0 -1 0" pos="0 0 0" springref="0" stiffness="0.242" damping="0.092" />
                        <geom type="cylinder" fromto="0 0 0 0 0 -0.0720" size="0.0100000" mass="0" />
                        <geom name="geom_whip_node4" type="sphere" material="pointMassColor" pos="0 0 -0.0720" size="0.0200000" mass="0.0120000" />
                        <body name="body_whip_node5" euler="0 0 0" pos="0 0 -0.0720">
                          <!-- <joint name="joint_whip_node5_X" type="hinge" axis="1  0 0" pos="0 0 0" springref="0" stiffness="0.242" damping="0.092" /> -->
                          <joint name="joint_whip_node5_Y" type="hinge" axis="0 -1 0" pos="0 0 0" springref="0" stiffness="0.242" damping="0.092" />
                           <geom type="cylinder" fromto="0 0 0 0 0 -0.0720" size="0.0100000" mass="0" />
                           <geom name="geom_whip_node5" type="sphere" material="pointMassColor" pos="0 0 -0.0720" size="0.0200000" mass="0.0120000" />
                           <body name="body_whip_node6" euler="0 0 0" pos="0 0 -0.0720">
                             <!-- <joint name="joint_whip_node6_X" type="hinge" axis="1  0 0" pos="0 0 0" springref="0" stiffness="0.242" damping="0.092" /> -->
                             <joint name="joint_whip_node6_Y" type="hinge" axis="0 -1 0" pos="0 0 0" springref="0" stiffness="0.242" damping="0.092" />
                              <geom type="cylinder" fromto="0 0 0 0 0 -0.0720" size="0.0100000" mass="0" />
                              <geom name="geom_whip_node6" type="sphere" material="pointMassColor" pos="0 0 -0.0720" size="0.0200000" mass="0.0120000" />
                              <body name="body_whip_node7" euler="0 0 0" pos="0 0 -0.0720">
                                <!-- <joint name="joint_whip_node7_X" type="hinge" axis="1  0 0" pos="0 0 0" springref="0" stiffness="0.242" damping="0.092" />                               -->
                                <joint name="joint_whip_node7_Y" type="hinge" axis="0 -1 0" pos="0 0 0" springref="0" stiffness="0.242" damping="0.092" />
                                 <geom type="cylinder" fromto="0 0 0 0 0 -0.0720" size="0.0100000" mass="0" />
                                 <geom name="geom_whip_node7" type="sphere" material="pointMassColor" pos="0 0 -0.0720" size="0.0200000" mass="0.0120000" />
                                 <body name="body_whip_node8" euler="0 0 0" pos="0 0 -0.0720">
                                   <!-- <joint name="joint_whip_node8_X" type="hinge" axis="1  0 0" pos="0 0 0" springref="0" stiffness="0.242" damping="0.092" />                                                                -->
                                   <joint name="joint_whip_node8_Y" type="hinge" axis="0 -1 0" pos="0 0 0" springref="0" stiffness="0.242" damping="0.092" />
                                    <geom type="cylinder" fromto="0 0 0 0 0 -0.0720" size="0.0100000" mass="0" />
                                    <geom name="geom_whip_node8" type="sphere" material="pointMassColor" pos="0 0 -0.0720" size="0.0200000" mass="0.0120000" />
                                    <body name="body_whip_node9" euler="0 0 0" pos="0 0 -0.0720">
                                      <!-- <joint name="joint_whip_node9_X" type="hinge" axis="1  0 0" pos="0 0 0" springref="0" stiffness="0.242" damping="0.092" />                                                                -->
                                      <joint name="joint_whip_node9_Y" type="hinge" axis="0 -1 0" pos="0 0 0" springref="0" stiffness="0.242" damping="0.092" />
                                       <geom type="cylinder" fromto="0 0 0 0 0 -0.0720" size="0.0100000" mass="0" />
                                       <geom name="geom_whip_node9" type="sphere" material="pointMassColor" pos="0 0 -0.0720" size="0.0200000" mass="0.0120000" />
                                       <body name="body_whip_node10" euler="0 0 0" pos="0 0 -0.0720">
                                         <!-- <joint name="joint_whip_node10_X" type="hinge" axis="1  0 0" pos="0 0 0" springref="0" stiffness="0.242" damping="0.092" />                                                                                                       -->
                                         <joint name="joint_whip_node10_Y" type="hinge" axis="0 -1 0" pos="0 0 0" springref="0" stiffness="0.242" damping="0.092" />
                                          <geom type="cylinder" fromto="0 0 0 0 0 -0.0720" size="0.0100000" mass="0" />
                                          <geom name="geom_whip_node10" type="sphere" material="pointMassColor" pos="0 0 -0.0720" size="0.0200000" mass="0.0120000" />
                                          <body name="body_whip_node11" euler="0 0 0" pos="0 0 -0.0720">
                                            <!-- <joint name="joint_whip_node11_X" type="hinge" axis="1  0 0" pos="0 0 0" springref="0" stiffness="0.242" damping="0.092" />                                                                                                       -->
                                            <joint name="joint_whip_node11_Y" type="hinge" axis="0 -1 0" pos="0 0 0" springref="0" stiffness="0.242" damping="0.092" />
                                             <geom type="cylinder" fromto="0 0 0 0 0 -0.0720" size="0.0100000" mass="0" />
                                             <geom name="geom_whip_node11" type="sphere" material="pointMassColor" pos="0 0 -0.0720" size="0.0200000" mass="0.0120000" />
                                             <body name="body_whip_node12" euler="0 0 0" pos="0 0 -0.0720">
                                               <!-- <joint name="joint_whip_node12_X" type="hinge" axis="1  0 0" pos="0 0 0" springref="0" stiffness="0.242" damping="0.092" />                                                                                                                                                    -->
                                               <joint name="joint_whip_node12_Y" type="hinge" axis="0 -1 0" pos="0 0 0" springref="0" stiffness="0.242" damping="0.092" />
                                                <geom type="cylinder" fromto="0 0 0 0 0 -0.0720" size="0.0100000" mass="0" />
                                                <geom name="geom_whip_node12" type="sphere" material="pointMassColor" pos="0 0 -0.0720" size="0.0200000" mass="0.0120000" />
                                                <body name="body_whip_node13" euler="0 0 0" pos="0 0 -0.0720">
                                                  <!-- <joint name="joint_whip_node13_X" type="hinge" axis="1  0 0" pos="0 0 0" springref="0" stiffness="0.242" damping="0.092" />                                                                                                                                                                                                    -->
                                                  <joint name="joint_whip_node13_Y" type="hinge" axis="0 -1 0" pos="0 0 0" springref="0" stiffness="0.242" damping="0.092" />
                                                   <geom type="cylinder" fromto="0 0 0 0 0 -0.0720" size="0.0100000" mass="0" />
                                                   <geom name="geom_whip_node13" type="sphere" material="pointMassColor" pos="0 0 -0.0720" size="0.0200000" mass="0.0120000" />
                                                   <body name="body_whip_node14" euler="0 0 0" pos="0 0 -0.0720">
                                                     <!-- <joint name="joint_whip_node14_X" type="hinge" axis="1  0 0" pos="0 0 0" springref="0" stiffness="0.242" damping="0.092" />                                                                                                                                                                                                    -->
                                                     <joint name="joint_whip_node14_Y" type="hinge" axis="0 -1 0" pos="0 0 0" springref="0" stiffness="0.242" damping="0.092" />
                                                      <geom type="cylinder" fromto="0 0 0 0 0 -0.0720" size="0.0100000" mass="0" />
                                                      <geom name="geom_whip_node14" type="sphere" material="pointMassColor" pos="0 0 -0.0720" size="0.0200000" mass="0.0120000" />
                                                      <body name="body_whip_node15" euler="0 0 0" pos="0 0 -0.0720">
                                                        <!-- <joint name="joint_whip_node15_X" type="hinge" axis="1  0 0" pos="0 0 0" springref="0" stiffness="0.242" damping="0.092" />                                                                                                                                                                                                    -->
                                                        <joint name="joint_whip_node15_Y" type="hinge" axis="0 -1 0" pos="0 0 0" springref="0" stiffness="0.242" damping="0.092" />
                                                         <geom type="cylinder" fromto="0 0 0 0 0 -0.0720" size="0.0100000" mass="0" />
                                                         <geom name="geom_whip_node15" type="sphere" material="pointMassColor" pos="0 0 -0.0720" size="0.0200000" mass="0.0120000" />
                                                         <body name="body_whip_node16" euler="0 0 0" pos="0 0 -0.0720">
                                                           <!-- <joint name="joint_whip_node16_X" type="hinge" axis="1  0 0" pos="0 0 0" springref="0" stiffness="0.242" damping="0.092" />                                                                                                                                                                                                    -->
                                                           <joint name="joint_whip_node16_Y" type="hinge" axis="0 -1 0" pos="0 0 0" springref="0" stiffness="0.242" damping="0.092" />
                                                            <geom type="cylinder" fromto="0 0 0 0 0 -0.0720" size="0.0100000" mass="0" />
                                                            <geom name="geom_whip_node16" type="sphere" material="pointMassColor" pos="0 0 -0.0720" size="0.0200000" mass="0.0120000" />
                                                            <body name="body_whip_node17" euler="0 0 0" pos="0 0 -0.0720">
                                                              <!-- <joint name="joint_whip_node17_X" type="hinge" axis="1  0 0" pos="0 0 0" springref="0" stiffness="0.242" damping="0.092" />                                                                                                                                                                                                                                                                -->
                                                              <joint name="joint_whip_node17_Y" type="hinge" axis="0 -1 0" pos="0 0 0" springref="0" stiffness="0.242" damping="0.092" />
                                                               <geom type="cylinder" fromto="0 0 0 0 0 -0.0720" size="0.0100000" mass="0" />
                                                               <geom name="geom_whip_node17" type="sphere" material="pointMassColor" pos="0 0 -0.0720" size="0.0200000" mass="0.0120000" />
                                                               <body name="body_whip_node18" euler="0 0 0" pos="0 0 -0.0720">
                                                                 <!-- <joint name="joint_whip_node18_X" type="hinge" axis="1  0 0" pos="0 0 0" springref="0" stiffness="0.242" damping="0.092" />                                                                                                                                                                                                                                                                -->
                                                                 <joint name="joint_whip_node18_Y" type="hinge" axis="0 -1 0" pos="0 0 0" springref="0" stiffness="0.242" damping="0.092" />
                                                                  <geom type="cylinder" fromto="0 0 0 0 0 -0.0720" size="0.0100000" mass="0" />
                                                                  <geom name="geom_whip_node18" type="sphere" material="pointMassColor" pos="0 0 -0.0720" size="0.0200000" mass="0.0120000" />
                                                                  <body name="body_whip_node19" euler="0 0 0" pos="0 0 -0.0720">
                                                                    <!-- <joint name="joint_whip_node19_X" type="hinge" axis="1  0 0" pos="0 0 0" springref="0" stiffness="0.242" damping="0.092" />                                                                                                                                                                                                                                                                -->
                                                                    <joint name="joint_whip_node19_Y" type="hinge" axis="0 -1 0" pos="0 0 0" springref="0" stiffness="0.242" damping="0.092" />
                                                                     <geom type="cylinder" fromto="0 0 0 0 0 -0.0720" size="0.0100000" mass="0" />
                                                                     <geom name="geom_whip_node19" type="sphere" material="pointMassColor" pos="0 0 -0.0720" size="0.0200000" mass="0.0120000" />
                                                                     <body name="body_whip_node20" euler="0 0 0" pos="0 0 -0.0720">
                                                                       <!-- <joint name="joint_whip_node20_X" type="hinge" axis="1  0 0" pos="0 0 0" springref="0" stiffness="0.242" damping="0.092" />                                                                                                                                                                                                                                                                                                                                     -->
                                                                       <joint name="joint_whip_node20_Y" type="hinge" axis="0 -1 0" pos="0 0 0" springref="0" stiffness="0.242" damping="0.092" />
                                                                        <geom type="cylinder" fromto="0 0 0 0 0 -0.0720" size="0.0100000" mass="0" />
                                                                        <geom name="geom_whip_node20" type="sphere" material="pointMassColor" pos="0 0 -0.0720" size="0.0200000" mass="0.0120000" />
                                                                        <body name="body_whip_node21" euler="0 0 0" pos="0 0 -0.0720">
                                                                          <!-- <joint name="joint_whip_node21_X" type="hinge" axis="1  0 0" pos="0 0 0" springref="0" stiffness="0.242" damping="0.092" />                                                                                                                                                                                                                                                                                                                                     -->
                                                                          <joint name="joint_whip_node21_Y" type="hinge" axis="0 -1 0" pos="0 0 0" springref="0" stiffness="0.242" damping="0.092" />
                                                                           <geom type="cylinder" fromto="0 0 0 0 0 -0.0720" size="0.0100000" mass="0" />
                                                                           <geom name="geom_whip_node21" type="sphere" material="pointMassColor" pos="0 0 -0.0720" size="0.0200000" mass="0.0120000" />
                                                                           <body name="body_whip_node22" euler="0 0 0" pos="0 0 -0.0720">
                                                                             <!-- <joint name="joint_whip_node22_X" type="hinge" axis="1  0 0" pos="0 0 0" springref="0" stiffness="0.242" damping="0.092" />                                                                                                                                                                                                                                                                                                                                                                                                                -->
                                                                             <joint name="joint_whip_node22_Y" type="hinge" axis="0 -1 0" pos="0 0 0" springref="0" stiffness="0.242" damping="0.092" />
                                                                              <geom type="cylinder" fromto="0 0 0 0 0 -0.0720" size="0.0100000" mass="0" />
                                                                              <geom name="geom_whip_node22" type="sphere" material="pointMassColor" pos="0 0 -0.0720" size="0.0200000" mass="0.0120000" />
                                                                              <body name="body_whip_node23" euler="0 0 0" pos="0 0 -0.0720">
                                                                                <!-- <joint name="joint_whip_node23_X" type="hinge" axis="1  0 0" pos="0 0 0" springref="0" stiffness="0.242" damping="0.092" />                                                                                                                                                                                                                                                                                                                                                                                                                -->
                                                                                <joint name="joint_whip_node23_Y" type="hinge" axis="0 -1 0" pos="0 0 0" springref="0" stiffness="0.242" damping="0.092" />
                                                                                 <geom type="cylinder" fromto="0 0 0 0 0 -0.0720" size="0.0100000" mass="0" />
                                                                                 <geom name="geom_whip_node23" type="sphere" material="pointMassColor" pos="0 0 -0.0720" size="0.0200000" mass="0.0120000" />
                                                                                 <body name="body_whip_node24" euler="0 0 0" pos="0 0 -0.0720">
                                                                                   <!-- <joint name="joint_whip_node24_X" type="hinge" axis="1  0 0" pos="0 0 0" springref="0" stiffness="0.242" damping="0.092" />                                                                                                                                                                                                                                                                                                                                                                                                                                                                                                 -->
                                                                                   <joint name="joint_whip_node24_Y" type="hinge" axis="0 -1 0" pos="0 0 0" springref="0" stiffness="0.242" damping="0.092" />
                                                                                    <geom type="cylinder" fromto="0 0 0 0 0 -0.0720" size="0.0100000" mass="0" />
                                                                                    <geom name="geom_whip_node24" type="sphere" material="pointMassColor" pos="0 0 -0.0720" size="0.0200000" mass="0.0120000" />
                                                                                    <body name="body_whip_node25" euler="0 0 0" pos="0 0 -0.0720">
                                                                                      <!-- <joint name="joint_whip_node25_X" type="hinge" axis="1  0 0" pos="0 0 0" springref="0" stiffness="0.242" damping="0.092" />                                                                                                                                                                                                                                                                                                                                                                                                                                                                                                 -->
                                                                                      <joint name="joint_whip_node25_Y" type="hinge" axis="0 -1 0" pos="0 0 0" springref="0" stiffness="0.242" damping="0.092" />
                                                                                       <geom type="cylinder" fromto="0 0 0 0 0 -0.0720" size="0.0100000" mass="0" />
                                                                                       <geom name="geom_whip_node25" type="sphere" material="pointMassColor" pos="0 0 -0.0720" size="0.0200000" mass="0.0120000" />
                                                                                       <site name='site_whip_tip' pos='0 0 -0.0720' /> 
                                                                                    </body>
                                                                                 </body>
                                                                              </body>
                                                                           </body>
                                                                        </body>
                                                                     </body>
                                                                  </body>
                                                               </body>
                                                            </body>
                                                         </body>
                                                      </body>
                                                   </body>
                                                </body>
                                             </body>
                                          </body>
                                       </body>
                                    </body>
                                 </body>
                              </body>
                           </body>
                        </body>
                     </body>
                  </body>
               </body>
            </body>
            
        </body>
    

   </worldbody>

   <actuator>
      <position joint="joint_excitator" name="excitator_joint_Pgain" kp="500000" />
      <velocity joint="joint_excitator" name="excitator_joint_Dgain" kv=" 5000" />
   </actuator>

</mujoco>
